2025-06-04 19:43:25,776 [WEB] ERROR pipeline error
Traceback (most recent call last):
  File "D:\UPBIT_ML\f5_ml_pipeline\run_pipeline.py", line 57, in _acquire_lock
    msvcrt.locking(fh.fileno(), msvcrt.LK_NBLCK, 1)
PermissionError: [Errno 13] Permission denied

During handling of the above exception, another exception occurred:

Traceback (most recent call last):
  File "D:\UPBIT_ML\app.py", line 326, in worker
    module.main()
  File "D:\UPBIT_ML\f5_ml_pipeline\run_pipeline.py", line 99, in main
    lock = _acquire_lock()
  File "D:\UPBIT_ML\f5_ml_pipeline\run_pipeline.py", line 64, in _acquire_lock
    msvcrt.locking(fh.fileno(), msvcrt.LK_UNLCK, 1)
PermissionError: [Errno 13] Permission denied
2025-06-04 19:50:15,860 [WEB] ERROR pipeline error
Traceback (most recent call last):
  File "D:\UPBIT_ML\f5_ml_pipeline\run_pipeline.py", line 57, in _acquire_lock
    msvcrt.locking(fh.fileno(), msvcrt.LK_NBLCK, 1)
PermissionError: [Errno 13] Permission denied

During handling of the above exception, another exception occurred:

Traceback (most recent call last):
  File "D:\UPBIT_ML\app.py", line 326, in worker
    module.main()
  File "D:\UPBIT_ML\f5_ml_pipeline\run_pipeline.py", line 99, in main
    lock = _acquire_lock()
  File "D:\UPBIT_ML\f5_ml_pipeline\run_pipeline.py", line 64, in _acquire_lock
    msvcrt.locking(fh.fileno(), msvcrt.LK_UNLCK, 1)
PermissionError: [Errno 13] Permission denied
2025-06-04 19:55:27,250 [WEB] ERROR pipeline error
Traceback (most recent call last):
  File "D:\UPBIT_ML\f5_ml_pipeline\run_pipeline.py", line 57, in _acquire_lock
    msvcrt.locking(fh.fileno(), msvcrt.LK_NBLCK, 1)
PermissionError: [Errno 13] Permission denied

During handling of the above exception, another exception occurred:

Traceback (most recent call last):
  File "D:\UPBIT_ML\app.py", line 326, in worker
    module.main()
  File "D:\UPBIT_ML\f5_ml_pipeline\run_pipeline.py", line 99, in main
    lock = _acquire_lock()
  File "D:\UPBIT_ML\f5_ml_pipeline\run_pipeline.py", line 64, in _acquire_lock
    msvcrt.locking(fh.fileno(), msvcrt.LK_UNLCK, 1)
PermissionError: [Errno 13] Permission denied
2025-06-04 20:02:15,247 [WEB] ERROR pipeline error
Traceback (most recent call last):
  File "D:\UPBIT_ML\f5_ml_pipeline\run_pipeline.py", line 57, in _acquire_lock
    msvcrt.locking(fh.fileno(), msvcrt.LK_NBLCK, 1)
PermissionError: [Errno 13] Permission denied

During handling of the above exception, another exception occurred:

Traceback (most recent call last):
  File "D:\UPBIT_ML\app.py", line 326, in worker
    module.main()
  File "D:\UPBIT_ML\f5_ml_pipeline\run_pipeline.py", line 99, in main
    lock = _acquire_lock()
  File "D:\UPBIT_ML\f5_ml_pipeline\run_pipeline.py", line 64, in _acquire_lock
    msvcrt.locking(fh.fileno(), msvcrt.LK_UNLCK, 1)
PermissionError: [Errno 13] Permission denied
2025-06-04 20:07:31,632 [WEB] ERROR pipeline error
Traceback (most recent call last):
  File "D:\UPBIT_ML\f5_ml_pipeline\run_pipeline.py", line 57, in _acquire_lock
    msvcrt.locking(fh.fileno(), msvcrt.LK_NBLCK, 1)
PermissionError: [Errno 13] Permission denied

During handling of the above exception, another exception occurred:

Traceback (most recent call last):
  File "D:\UPBIT_ML\app.py", line 326, in worker
    module.main()
  File "D:\UPBIT_ML\f5_ml_pipeline\run_pipeline.py", line 99, in main
    lock = _acquire_lock()
  File "D:\UPBIT_ML\f5_ml_pipeline\run_pipeline.py", line 64, in _acquire_lock
    msvcrt.locking(fh.fileno(), msvcrt.LK_UNLCK, 1)
PermissionError: [Errno 13] Permission denied
2025-06-04 20:14:26,511 [WEB] ERROR pipeline error
Traceback (most recent call last):
  File "D:\UPBIT_ML\f5_ml_pipeline\run_pipeline.py", line 57, in _acquire_lock
    msvcrt.locking(fh.fileno(), msvcrt.LK_NBLCK, 1)
PermissionError: [Errno 13] Permission denied

During handling of the above exception, another exception occurred:

Traceback (most recent call last):
  File "D:\UPBIT_ML\app.py", line 326, in worker
    module.main()
  File "D:\UPBIT_ML\f5_ml_pipeline\run_pipeline.py", line 99, in main
    lock = _acquire_lock()
  File "D:\UPBIT_ML\f5_ml_pipeline\run_pipeline.py", line 64, in _acquire_lock
    msvcrt.locking(fh.fileno(), msvcrt.LK_UNLCK, 1)
PermissionError: [Errno 13] Permission denied
2025-06-04 20:19:52,566 [WEB] ERROR pipeline error
Traceback (most recent call last):
  File "D:\UPBIT_ML\f5_ml_pipeline\run_pipeline.py", line 57, in _acquire_lock
    msvcrt.locking(fh.fileno(), msvcrt.LK_NBLCK, 1)
PermissionError: [Errno 13] Permission denied

During handling of the above exception, another exception occurred:

Traceback (most recent call last):
  File "D:\UPBIT_ML\app.py", line 326, in worker
    module.main()
  File "D:\UPBIT_ML\f5_ml_pipeline\run_pipeline.py", line 99, in main
    lock = _acquire_lock()
  File "D:\UPBIT_ML\f5_ml_pipeline\run_pipeline.py", line 64, in _acquire_lock
    msvcrt.locking(fh.fileno(), msvcrt.LK_UNLCK, 1)
PermissionError: [Errno 13] Permission denied
2025-06-04 20:27:06,739 [WEB] ERROR pipeline error
Traceback (most recent call last):
  File "D:\UPBIT_ML\f5_ml_pipeline\run_pipeline.py", line 57, in _acquire_lock
    msvcrt.locking(fh.fileno(), msvcrt.LK_NBLCK, 1)
PermissionError: [Errno 13] Permission denied

During handling of the above exception, another exception occurred:

Traceback (most recent call last):
  File "D:\UPBIT_ML\app.py", line 326, in worker
    module.main()
  File "D:\UPBIT_ML\f5_ml_pipeline\run_pipeline.py", line 99, in main
    lock = _acquire_lock()
  File "D:\UPBIT_ML\f5_ml_pipeline\run_pipeline.py", line 64, in _acquire_lock
    msvcrt.locking(fh.fileno(), msvcrt.LK_UNLCK, 1)
PermissionError: [Errno 13] Permission denied
2025-06-04 20:32:36,322 [WEB] ERROR pipeline error
Traceback (most recent call last):
  File "D:\UPBIT_ML\f5_ml_pipeline\run_pipeline.py", line 57, in _acquire_lock
    msvcrt.locking(fh.fileno(), msvcrt.LK_NBLCK, 1)
PermissionError: [Errno 13] Permission denied

During handling of the above exception, another exception occurred:

Traceback (most recent call last):
  File "D:\UPBIT_ML\app.py", line 326, in worker
    module.main()
  File "D:\UPBIT_ML\f5_ml_pipeline\run_pipeline.py", line 99, in main
    lock = _acquire_lock()
  File "D:\UPBIT_ML\f5_ml_pipeline\run_pipeline.py", line 64, in _acquire_lock
    msvcrt.locking(fh.fileno(), msvcrt.LK_UNLCK, 1)
PermissionError: [Errno 13] Permission denied
2025-06-04 20:41:56,443 [WEB] ERROR pipeline error
Traceback (most recent call last):
  File "D:\UPBIT_ML\f5_ml_pipeline\run_pipeline.py", line 57, in _acquire_lock
    msvcrt.locking(fh.fileno(), msvcrt.LK_NBLCK, 1)
PermissionError: [Errno 13] Permission denied

During handling of the above exception, another exception occurred:

Traceback (most recent call last):
  File "D:\UPBIT_ML\app.py", line 326, in worker
    module.main()
  File "D:\UPBIT_ML\f5_ml_pipeline\run_pipeline.py", line 99, in main
    lock = _acquire_lock()
  File "D:\UPBIT_ML\f5_ml_pipeline\run_pipeline.py", line 64, in _acquire_lock
    msvcrt.locking(fh.fileno(), msvcrt.LK_UNLCK, 1)
PermissionError: [Errno 13] Permission denied
2025-06-04 20:47:15,209 [WEB] ERROR pipeline error
Traceback (most recent call last):
  File "D:\UPBIT_ML\f5_ml_pipeline\run_pipeline.py", line 57, in _acquire_lock
    msvcrt.locking(fh.fileno(), msvcrt.LK_NBLCK, 1)
PermissionError: [Errno 13] Permission denied

During handling of the above exception, another exception occurred:

Traceback (most recent call last):
  File "D:\UPBIT_ML\app.py", line 326, in worker
    module.main()
  File "D:\UPBIT_ML\f5_ml_pipeline\run_pipeline.py", line 99, in main
    lock = _acquire_lock()
  File "D:\UPBIT_ML\f5_ml_pipeline\run_pipeline.py", line 64, in _acquire_lock
    msvcrt.locking(fh.fileno(), msvcrt.LK_UNLCK, 1)
PermissionError: [Errno 13] Permission denied
2025-06-04 20:53:07,608 [WEB] ERROR pipeline error
Traceback (most recent call last):
  File "D:\UPBIT_ML\f5_ml_pipeline\run_pipeline.py", line 57, in _acquire_lock
    msvcrt.locking(fh.fileno(), msvcrt.LK_NBLCK, 1)
PermissionError: [Errno 13] Permission denied

During handling of the above exception, another exception occurred:

Traceback (most recent call last):
  File "D:\UPBIT_ML\app.py", line 326, in worker
    module.main()
  File "D:\UPBIT_ML\f5_ml_pipeline\run_pipeline.py", line 99, in main
    lock = _acquire_lock()
  File "D:\UPBIT_ML\f5_ml_pipeline\run_pipeline.py", line 64, in _acquire_lock
    msvcrt.locking(fh.fileno(), msvcrt.LK_UNLCK, 1)
PermissionError: [Errno 13] Permission denied
2025-06-04 21:01:50,425 [WEB] ERROR pipeline error
Traceback (most recent call last):
  File "D:\UPBIT_ML\f5_ml_pipeline\run_pipeline.py", line 57, in _acquire_lock
    msvcrt.locking(fh.fileno(), msvcrt.LK_NBLCK, 1)
PermissionError: [Errno 13] Permission denied

During handling of the above exception, another exception occurred:

Traceback (most recent call last):
  File "D:\UPBIT_ML\app.py", line 326, in worker
    module.main()
  File "D:\UPBIT_ML\f5_ml_pipeline\run_pipeline.py", line 99, in main
    lock = _acquire_lock()
  File "D:\UPBIT_ML\f5_ml_pipeline\run_pipeline.py", line 64, in _acquire_lock
    msvcrt.locking(fh.fileno(), msvcrt.LK_UNLCK, 1)
PermissionError: [Errno 13] Permission denied
2025-06-04 21:06:56,863 [WEB] ERROR pipeline error
Traceback (most recent call last):
  File "D:\UPBIT_ML\f5_ml_pipeline\run_pipeline.py", line 57, in _acquire_lock
    msvcrt.locking(fh.fileno(), msvcrt.LK_NBLCK, 1)
PermissionError: [Errno 13] Permission denied

During handling of the above exception, another exception occurred:

Traceback (most recent call last):
  File "D:\UPBIT_ML\app.py", line 326, in worker
    module.main()
  File "D:\UPBIT_ML\f5_ml_pipeline\run_pipeline.py", line 99, in main
    lock = _acquire_lock()
  File "D:\UPBIT_ML\f5_ml_pipeline\run_pipeline.py", line 64, in _acquire_lock
    msvcrt.locking(fh.fileno(), msvcrt.LK_UNLCK, 1)
PermissionError: [Errno 13] Permission denied
2025-06-04 21:15:42,909 [WEB] ERROR pipeline error
Traceback (most recent call last):
  File "D:\UPBIT_ML\f5_ml_pipeline\run_pipeline.py", line 57, in _acquire_lock
    msvcrt.locking(fh.fileno(), msvcrt.LK_NBLCK, 1)
PermissionError: [Errno 13] Permission denied

During handling of the above exception, another exception occurred:

Traceback (most recent call last):
  File "D:\UPBIT_ML\app.py", line 326, in worker
    module.main()
  File "D:\UPBIT_ML\f5_ml_pipeline\run_pipeline.py", line 99, in main
    lock = _acquire_lock()
  File "D:\UPBIT_ML\f5_ml_pipeline\run_pipeline.py", line 64, in _acquire_lock
    msvcrt.locking(fh.fileno(), msvcrt.LK_UNLCK, 1)
PermissionError: [Errno 13] Permission denied
2025-06-04 21:20:49,797 [WEB] ERROR pipeline error
Traceback (most recent call last):
  File "D:\UPBIT_ML\f5_ml_pipeline\run_pipeline.py", line 57, in _acquire_lock
    msvcrt.locking(fh.fileno(), msvcrt.LK_NBLCK, 1)
PermissionError: [Errno 13] Permission denied

During handling of the above exception, another exception occurred:

Traceback (most recent call last):
  File "D:\UPBIT_ML\app.py", line 326, in worker
    module.main()
  File "D:\UPBIT_ML\f5_ml_pipeline\run_pipeline.py", line 99, in main
    lock = _acquire_lock()
  File "D:\UPBIT_ML\f5_ml_pipeline\run_pipeline.py", line 64, in _acquire_lock
    msvcrt.locking(fh.fileno(), msvcrt.LK_UNLCK, 1)
PermissionError: [Errno 13] Permission denied
2025-06-04 21:42:18,892 [WEB] ERROR pipeline error
Traceback (most recent call last):
  File "D:\UPBIT_ML\f5_ml_pipeline\run_pipeline.py", line 57, in _acquire_lock
    msvcrt.locking(fh.fileno(), msvcrt.LK_NBLCK, 1)
PermissionError: [Errno 13] Permission denied

During handling of the above exception, another exception occurred:

Traceback (most recent call last):
  File "D:\UPBIT_ML\app.py", line 326, in worker
    module.main()
  File "D:\UPBIT_ML\f5_ml_pipeline\run_pipeline.py", line 99, in main
    lock = _acquire_lock()
  File "D:\UPBIT_ML\f5_ml_pipeline\run_pipeline.py", line 64, in _acquire_lock
    msvcrt.locking(fh.fileno(), msvcrt.LK_UNLCK, 1)
PermissionError: [Errno 13] Permission denied
2025-06-04 21:47:51,279 [WEB] ERROR pipeline error
Traceback (most recent call last):
  File "D:\UPBIT_ML\f5_ml_pipeline\run_pipeline.py", line 57, in _acquire_lock
    msvcrt.locking(fh.fileno(), msvcrt.LK_NBLCK, 1)
PermissionError: [Errno 13] Permission denied

During handling of the above exception, another exception occurred:

Traceback (most recent call last):
  File "D:\UPBIT_ML\app.py", line 326, in worker
    module.main()
  File "D:\UPBIT_ML\f5_ml_pipeline\run_pipeline.py", line 99, in main
    lock = _acquire_lock()
  File "D:\UPBIT_ML\f5_ml_pipeline\run_pipeline.py", line 64, in _acquire_lock
    msvcrt.locking(fh.fileno(), msvcrt.LK_UNLCK, 1)
PermissionError: [Errno 13] Permission denied
2025-06-04 22:00:45,993 [WEB] ERROR pipeline error
Traceback (most recent call last):
  File "D:\UPBIT_ML\f5_ml_pipeline\run_pipeline.py", line 57, in _acquire_lock
    msvcrt.locking(fh.fileno(), msvcrt.LK_NBLCK, 1)
PermissionError: [Errno 13] Permission denied

During handling of the above exception, another exception occurred:

Traceback (most recent call last):
  File "D:\UPBIT_ML\app.py", line 326, in worker
    module.main()
  File "D:\UPBIT_ML\f5_ml_pipeline\run_pipeline.py", line 99, in main
    lock = _acquire_lock()
  File "D:\UPBIT_ML\f5_ml_pipeline\run_pipeline.py", line 64, in _acquire_lock
    msvcrt.locking(fh.fileno(), msvcrt.LK_UNLCK, 1)
PermissionError: [Errno 13] Permission denied
2025-06-04 22:06:02,200 [WEB] ERROR pipeline error
Traceback (most recent call last):
  File "D:\UPBIT_ML\f5_ml_pipeline\run_pipeline.py", line 57, in _acquire_lock
    msvcrt.locking(fh.fileno(), msvcrt.LK_NBLCK, 1)
PermissionError: [Errno 13] Permission denied

During handling of the above exception, another exception occurred:

Traceback (most recent call last):
  File "D:\UPBIT_ML\app.py", line 326, in worker
    module.main()
  File "D:\UPBIT_ML\f5_ml_pipeline\run_pipeline.py", line 99, in main
    lock = _acquire_lock()
  File "D:\UPBIT_ML\f5_ml_pipeline\run_pipeline.py", line 64, in _acquire_lock
    msvcrt.locking(fh.fileno(), msvcrt.LK_UNLCK, 1)
PermissionError: [Errno 13] Permission denied
2025-06-04 22:13:17,670 [WEB] ERROR pipeline error
Traceback (most recent call last):
  File "D:\UPBIT_ML\f5_ml_pipeline\run_pipeline.py", line 57, in _acquire_lock
    msvcrt.locking(fh.fileno(), msvcrt.LK_NBLCK, 1)
PermissionError: [Errno 13] Permission denied

During handling of the above exception, another exception occurred:

Traceback (most recent call last):
  File "D:\UPBIT_ML\app.py", line 326, in worker
    module.main()
  File "D:\UPBIT_ML\f5_ml_pipeline\run_pipeline.py", line 99, in main
    lock = _acquire_lock()
  File "D:\UPBIT_ML\f5_ml_pipeline\run_pipeline.py", line 64, in _acquire_lock
    msvcrt.locking(fh.fileno(), msvcrt.LK_UNLCK, 1)
PermissionError: [Errno 13] Permission denied
2025-06-04 22:17:26,607 [WEB] ERROR pipeline error
Traceback (most recent call last):
  File "D:\UPBIT_ML\f5_ml_pipeline\run_pipeline.py", line 57, in _acquire_lock
    msvcrt.locking(fh.fileno(), msvcrt.LK_NBLCK, 1)
PermissionError: [Errno 13] Permission denied

During handling of the above exception, another exception occurred:

Traceback (most recent call last):
  File "D:\UPBIT_ML\app.py", line 326, in worker
    module.main()
  File "D:\UPBIT_ML\f5_ml_pipeline\run_pipeline.py", line 99, in main
    lock = _acquire_lock()
  File "D:\UPBIT_ML\f5_ml_pipeline\run_pipeline.py", line 64, in _acquire_lock
    msvcrt.locking(fh.fileno(), msvcrt.LK_UNLCK, 1)
PermissionError: [Errno 13] Permission denied
2025-06-04 22:31:58,360 [WEB] ERROR pipeline error
Traceback (most recent call last):
  File "D:\UPBIT_ML\f5_ml_pipeline\run_pipeline.py", line 57, in _acquire_lock
    msvcrt.locking(fh.fileno(), msvcrt.LK_NBLCK, 1)
PermissionError: [Errno 13] Permission denied

During handling of the above exception, another exception occurred:

Traceback (most recent call last):
  File "D:\UPBIT_ML\app.py", line 326, in worker
    module.main()
  File "D:\UPBIT_ML\f5_ml_pipeline\run_pipeline.py", line 99, in main
    lock = _acquire_lock()
  File "D:\UPBIT_ML\f5_ml_pipeline\run_pipeline.py", line 64, in _acquire_lock
    msvcrt.locking(fh.fileno(), msvcrt.LK_UNLCK, 1)
PermissionError: [Errno 13] Permission denied
2025-06-04 22:37:32,946 [WEB] ERROR pipeline error
Traceback (most recent call last):
  File "D:\UPBIT_ML\f5_ml_pipeline\run_pipeline.py", line 57, in _acquire_lock
    msvcrt.locking(fh.fileno(), msvcrt.LK_NBLCK, 1)
PermissionError: [Errno 13] Permission denied

During handling of the above exception, another exception occurred:

Traceback (most recent call last):
  File "D:\UPBIT_ML\app.py", line 326, in worker
    module.main()
  File "D:\UPBIT_ML\f5_ml_pipeline\run_pipeline.py", line 99, in main
    lock = _acquire_lock()
  File "D:\UPBIT_ML\f5_ml_pipeline\run_pipeline.py", line 64, in _acquire_lock
    msvcrt.locking(fh.fileno(), msvcrt.LK_UNLCK, 1)
PermissionError: [Errno 13] Permission denied
2025-06-04 22:44:26,529 [WEB] ERROR pipeline error
Traceback (most recent call last):
  File "D:\UPBIT_ML\f5_ml_pipeline\run_pipeline.py", line 57, in _acquire_lock
    msvcrt.locking(fh.fileno(), msvcrt.LK_NBLCK, 1)
PermissionError: [Errno 13] Permission denied

During handling of the above exception, another exception occurred:

Traceback (most recent call last):
  File "D:\UPBIT_ML\app.py", line 326, in worker
    module.main()
  File "D:\UPBIT_ML\f5_ml_pipeline\run_pipeline.py", line 99, in main
    lock = _acquire_lock()
  File "D:\UPBIT_ML\f5_ml_pipeline\run_pipeline.py", line 64, in _acquire_lock
    msvcrt.locking(fh.fileno(), msvcrt.LK_UNLCK, 1)
PermissionError: [Errno 13] Permission denied
2025-06-04 22:49:33,514 [WEB] ERROR pipeline error
Traceback (most recent call last):
  File "D:\UPBIT_ML\f5_ml_pipeline\run_pipeline.py", line 57, in _acquire_lock
    msvcrt.locking(fh.fileno(), msvcrt.LK_NBLCK, 1)
PermissionError: [Errno 13] Permission denied

During handling of the above exception, another exception occurred:

Traceback (most recent call last):
  File "D:\UPBIT_ML\app.py", line 326, in worker
    module.main()
  File "D:\UPBIT_ML\f5_ml_pipeline\run_pipeline.py", line 99, in main
    lock = _acquire_lock()
  File "D:\UPBIT_ML\f5_ml_pipeline\run_pipeline.py", line 64, in _acquire_lock
    msvcrt.locking(fh.fileno(), msvcrt.LK_UNLCK, 1)
PermissionError: [Errno 13] Permission denied
2025-06-04 23:15:43,469 [WEB] ERROR pipeline error
Traceback (most recent call last):
  File "D:\UPBIT_ML\f5_ml_pipeline\run_pipeline.py", line 57, in _acquire_lock
    msvcrt.locking(fh.fileno(), msvcrt.LK_NBLCK, 1)
PermissionError: [Errno 13] Permission denied

During handling of the above exception, another exception occurred:

Traceback (most recent call last):
  File "D:\UPBIT_ML\app.py", line 326, in worker
    module.main()
  File "D:\UPBIT_ML\f5_ml_pipeline\run_pipeline.py", line 99, in main
    lock = _acquire_lock()
  File "D:\UPBIT_ML\f5_ml_pipeline\run_pipeline.py", line 64, in _acquire_lock
    msvcrt.locking(fh.fileno(), msvcrt.LK_UNLCK, 1)
PermissionError: [Errno 13] Permission denied
2025-06-04 23:20:45,096 [WEB] ERROR pipeline error
Traceback (most recent call last):
  File "D:\UPBIT_ML\f5_ml_pipeline\run_pipeline.py", line 57, in _acquire_lock
    msvcrt.locking(fh.fileno(), msvcrt.LK_NBLCK, 1)
PermissionError: [Errno 13] Permission denied

During handling of the above exception, another exception occurred:

Traceback (most recent call last):
  File "D:\UPBIT_ML\app.py", line 326, in worker
    module.main()
  File "D:\UPBIT_ML\f5_ml_pipeline\run_pipeline.py", line 99, in main
    lock = _acquire_lock()
  File "D:\UPBIT_ML\f5_ml_pipeline\run_pipeline.py", line 64, in _acquire_lock
    msvcrt.locking(fh.fileno(), msvcrt.LK_UNLCK, 1)
PermissionError: [Errno 13] Permission denied
2025-06-04 23:28:57,694 [WEB] ERROR pipeline error
Traceback (most recent call last):
  File "D:\UPBIT_ML\f5_ml_pipeline\run_pipeline.py", line 57, in _acquire_lock
    msvcrt.locking(fh.fileno(), msvcrt.LK_NBLCK, 1)
PermissionError: [Errno 13] Permission denied

During handling of the above exception, another exception occurred:

Traceback (most recent call last):
  File "D:\UPBIT_ML\app.py", line 326, in worker
    module.main()
  File "D:\UPBIT_ML\f5_ml_pipeline\run_pipeline.py", line 99, in main
    lock = _acquire_lock()
  File "D:\UPBIT_ML\f5_ml_pipeline\run_pipeline.py", line 64, in _acquire_lock
    msvcrt.locking(fh.fileno(), msvcrt.LK_UNLCK, 1)
PermissionError: [Errno 13] Permission denied
2025-06-04 23:34:22,505 [WEB] ERROR pipeline error
Traceback (most recent call last):
  File "D:\UPBIT_ML\f5_ml_pipeline\run_pipeline.py", line 57, in _acquire_lock
    msvcrt.locking(fh.fileno(), msvcrt.LK_NBLCK, 1)
PermissionError: [Errno 13] Permission denied

During handling of the above exception, another exception occurred:

Traceback (most recent call last):
  File "D:\UPBIT_ML\app.py", line 326, in worker
    module.main()
  File "D:\UPBIT_ML\f5_ml_pipeline\run_pipeline.py", line 99, in main
    lock = _acquire_lock()
  File "D:\UPBIT_ML\f5_ml_pipeline\run_pipeline.py", line 64, in _acquire_lock
    msvcrt.locking(fh.fileno(), msvcrt.LK_UNLCK, 1)
PermissionError: [Errno 13] Permission denied
2025-06-04 23:41:58,922 [WEB] ERROR pipeline error
Traceback (most recent call last):
  File "D:\UPBIT_ML\f5_ml_pipeline\run_pipeline.py", line 57, in _acquire_lock
    msvcrt.locking(fh.fileno(), msvcrt.LK_NBLCK, 1)
PermissionError: [Errno 13] Permission denied

During handling of the above exception, another exception occurred:

Traceback (most recent call last):
  File "D:\UPBIT_ML\app.py", line 326, in worker
    module.main()
  File "D:\UPBIT_ML\f5_ml_pipeline\run_pipeline.py", line 99, in main
    lock = _acquire_lock()
  File "D:\UPBIT_ML\f5_ml_pipeline\run_pipeline.py", line 64, in _acquire_lock
    msvcrt.locking(fh.fileno(), msvcrt.LK_UNLCK, 1)
PermissionError: [Errno 13] Permission denied
2025-06-04 23:47:32,881 [WEB] ERROR pipeline error
Traceback (most recent call last):
  File "D:\UPBIT_ML\f5_ml_pipeline\run_pipeline.py", line 57, in _acquire_lock
    msvcrt.locking(fh.fileno(), msvcrt.LK_NBLCK, 1)
PermissionError: [Errno 13] Permission denied

During handling of the above exception, another exception occurred:

Traceback (most recent call last):
  File "D:\UPBIT_ML\app.py", line 326, in worker
    module.main()
  File "D:\UPBIT_ML\f5_ml_pipeline\run_pipeline.py", line 99, in main
    lock = _acquire_lock()
  File "D:\UPBIT_ML\f5_ml_pipeline\run_pipeline.py", line 64, in _acquire_lock
    msvcrt.locking(fh.fileno(), msvcrt.LK_UNLCK, 1)
PermissionError: [Errno 13] Permission denied
2025-06-04 23:55:12,697 [WEB] ERROR pipeline error
Traceback (most recent call last):
  File "D:\UPBIT_ML\f5_ml_pipeline\run_pipeline.py", line 57, in _acquire_lock
    msvcrt.locking(fh.fileno(), msvcrt.LK_NBLCK, 1)
PermissionError: [Errno 13] Permission denied

During handling of the above exception, another exception occurred:

Traceback (most recent call last):
  File "D:\UPBIT_ML\app.py", line 326, in worker
    module.main()
  File "D:\UPBIT_ML\f5_ml_pipeline\run_pipeline.py", line 99, in main
    lock = _acquire_lock()
  File "D:\UPBIT_ML\f5_ml_pipeline\run_pipeline.py", line 64, in _acquire_lock
    msvcrt.locking(fh.fileno(), msvcrt.LK_UNLCK, 1)
PermissionError: [Errno 13] Permission denied
2025-06-05 00:00:51,666 [WEB] ERROR pipeline error
Traceback (most recent call last):
  File "D:\UPBIT_ML\f5_ml_pipeline\run_pipeline.py", line 57, in _acquire_lock
    msvcrt.locking(fh.fileno(), msvcrt.LK_NBLCK, 1)
PermissionError: [Errno 13] Permission denied

During handling of the above exception, another exception occurred:

Traceback (most recent call last):
  File "D:\UPBIT_ML\app.py", line 326, in worker
    module.main()
  File "D:\UPBIT_ML\f5_ml_pipeline\run_pipeline.py", line 99, in main
    lock = _acquire_lock()
  File "D:\UPBIT_ML\f5_ml_pipeline\run_pipeline.py", line 64, in _acquire_lock
    msvcrt.locking(fh.fileno(), msvcrt.LK_UNLCK, 1)
PermissionError: [Errno 13] Permission denied
2025-06-05 00:08:12,562 [WEB] ERROR pipeline error
Traceback (most recent call last):
  File "D:\UPBIT_ML\f5_ml_pipeline\run_pipeline.py", line 57, in _acquire_lock
    msvcrt.locking(fh.fileno(), msvcrt.LK_NBLCK, 1)
PermissionError: [Errno 13] Permission denied

During handling of the above exception, another exception occurred:

Traceback (most recent call last):
  File "D:\UPBIT_ML\app.py", line 326, in worker
    module.main()
  File "D:\UPBIT_ML\f5_ml_pipeline\run_pipeline.py", line 99, in main
    lock = _acquire_lock()
  File "D:\UPBIT_ML\f5_ml_pipeline\run_pipeline.py", line 64, in _acquire_lock
    msvcrt.locking(fh.fileno(), msvcrt.LK_UNLCK, 1)
PermissionError: [Errno 13] Permission denied
2025-06-05 00:14:08,656 [WEB] ERROR pipeline error
Traceback (most recent call last):
  File "D:\UPBIT_ML\f5_ml_pipeline\run_pipeline.py", line 57, in _acquire_lock
    msvcrt.locking(fh.fileno(), msvcrt.LK_NBLCK, 1)
PermissionError: [Errno 13] Permission denied

During handling of the above exception, another exception occurred:

Traceback (most recent call last):
  File "D:\UPBIT_ML\app.py", line 326, in worker
    module.main()
  File "D:\UPBIT_ML\f5_ml_pipeline\run_pipeline.py", line 99, in main
    lock = _acquire_lock()
  File "D:\UPBIT_ML\f5_ml_pipeline\run_pipeline.py", line 64, in _acquire_lock
    msvcrt.locking(fh.fileno(), msvcrt.LK_UNLCK, 1)
PermissionError: [Errno 13] Permission denied
2025-06-05 00:22:26,020 [WEB] ERROR pipeline error
Traceback (most recent call last):
  File "D:\UPBIT_ML\f5_ml_pipeline\run_pipeline.py", line 57, in _acquire_lock
    msvcrt.locking(fh.fileno(), msvcrt.LK_NBLCK, 1)
PermissionError: [Errno 13] Permission denied

During handling of the above exception, another exception occurred:

Traceback (most recent call last):
  File "D:\UPBIT_ML\app.py", line 326, in worker
    module.main()
  File "D:\UPBIT_ML\f5_ml_pipeline\run_pipeline.py", line 99, in main
    lock = _acquire_lock()
  File "D:\UPBIT_ML\f5_ml_pipeline\run_pipeline.py", line 64, in _acquire_lock
    msvcrt.locking(fh.fileno(), msvcrt.LK_UNLCK, 1)
PermissionError: [Errno 13] Permission denied
2025-06-05 00:30:11,406 [WEB] ERROR pipeline error
Traceback (most recent call last):
  File "D:\UPBIT_ML\f5_ml_pipeline\run_pipeline.py", line 57, in _acquire_lock
    msvcrt.locking(fh.fileno(), msvcrt.LK_NBLCK, 1)
PermissionError: [Errno 13] Permission denied

During handling of the above exception, another exception occurred:

Traceback (most recent call last):
  File "D:\UPBIT_ML\app.py", line 326, in worker
    module.main()
  File "D:\UPBIT_ML\f5_ml_pipeline\run_pipeline.py", line 99, in main
    lock = _acquire_lock()
  File "D:\UPBIT_ML\f5_ml_pipeline\run_pipeline.py", line 64, in _acquire_lock
    msvcrt.locking(fh.fileno(), msvcrt.LK_UNLCK, 1)
PermissionError: [Errno 13] Permission denied
2025-06-05 00:35:19,970 [WEB] ERROR pipeline error
Traceback (most recent call last):
  File "D:\UPBIT_ML\f5_ml_pipeline\run_pipeline.py", line 57, in _acquire_lock
    msvcrt.locking(fh.fileno(), msvcrt.LK_NBLCK, 1)
PermissionError: [Errno 13] Permission denied

During handling of the above exception, another exception occurred:

Traceback (most recent call last):
  File "D:\UPBIT_ML\app.py", line 326, in worker
    module.main()
  File "D:\UPBIT_ML\f5_ml_pipeline\run_pipeline.py", line 99, in main
    lock = _acquire_lock()
  File "D:\UPBIT_ML\f5_ml_pipeline\run_pipeline.py", line 64, in _acquire_lock
    msvcrt.locking(fh.fileno(), msvcrt.LK_UNLCK, 1)
PermissionError: [Errno 13] Permission denied
2025-06-05 01:24:14,834 [WEB] ERROR pipeline error
Traceback (most recent call last):
  File "D:\UPBIT_ML\f5_ml_pipeline\run_pipeline.py", line 57, in _acquire_lock
    msvcrt.locking(fh.fileno(), msvcrt.LK_NBLCK, 1)
PermissionError: [Errno 13] Permission denied

During handling of the above exception, another exception occurred:

Traceback (most recent call last):
  File "D:\UPBIT_ML\app.py", line 326, in worker
    module.main()
  File "D:\UPBIT_ML\f5_ml_pipeline\run_pipeline.py", line 99, in main
    lock = _acquire_lock()
  File "D:\UPBIT_ML\f5_ml_pipeline\run_pipeline.py", line 64, in _acquire_lock
    msvcrt.locking(fh.fileno(), msvcrt.LK_UNLCK, 1)
PermissionError: [Errno 13] Permission denied
2025-06-05 01:29:22,811 [WEB] ERROR pipeline error
Traceback (most recent call last):
  File "D:\UPBIT_ML\f5_ml_pipeline\run_pipeline.py", line 57, in _acquire_lock
    msvcrt.locking(fh.fileno(), msvcrt.LK_NBLCK, 1)
PermissionError: [Errno 13] Permission denied

During handling of the above exception, another exception occurred:

Traceback (most recent call last):
  File "D:\UPBIT_ML\app.py", line 326, in worker
    module.main()
  File "D:\UPBIT_ML\f5_ml_pipeline\run_pipeline.py", line 99, in main
    lock = _acquire_lock()
  File "D:\UPBIT_ML\f5_ml_pipeline\run_pipeline.py", line 64, in _acquire_lock
    msvcrt.locking(fh.fileno(), msvcrt.LK_UNLCK, 1)
PermissionError: [Errno 13] Permission denied
2025-06-05 01:37:34,472 [WEB] ERROR pipeline error
Traceback (most recent call last):
  File "D:\UPBIT_ML\f5_ml_pipeline\run_pipeline.py", line 57, in _acquire_lock
    msvcrt.locking(fh.fileno(), msvcrt.LK_NBLCK, 1)
PermissionError: [Errno 13] Permission denied

During handling of the above exception, another exception occurred:

Traceback (most recent call last):
  File "D:\UPBIT_ML\app.py", line 326, in worker
    module.main()
  File "D:\UPBIT_ML\f5_ml_pipeline\run_pipeline.py", line 99, in main
    lock = _acquire_lock()
  File "D:\UPBIT_ML\f5_ml_pipeline\run_pipeline.py", line 64, in _acquire_lock
    msvcrt.locking(fh.fileno(), msvcrt.LK_UNLCK, 1)
PermissionError: [Errno 13] Permission denied
2025-06-05 01:42:48,147 [WEB] ERROR pipeline error
Traceback (most recent call last):
  File "D:\UPBIT_ML\f5_ml_pipeline\run_pipeline.py", line 57, in _acquire_lock
    msvcrt.locking(fh.fileno(), msvcrt.LK_NBLCK, 1)
PermissionError: [Errno 13] Permission denied

During handling of the above exception, another exception occurred:

Traceback (most recent call last):
  File "D:\UPBIT_ML\app.py", line 326, in worker
    module.main()
  File "D:\UPBIT_ML\f5_ml_pipeline\run_pipeline.py", line 99, in main
    lock = _acquire_lock()
  File "D:\UPBIT_ML\f5_ml_pipeline\run_pipeline.py", line 64, in _acquire_lock
    msvcrt.locking(fh.fileno(), msvcrt.LK_UNLCK, 1)
PermissionError: [Errno 13] Permission denied
2025-06-05 01:50:51,792 [WEB] ERROR pipeline error
Traceback (most recent call last):
  File "D:\UPBIT_ML\f5_ml_pipeline\run_pipeline.py", line 57, in _acquire_lock
    msvcrt.locking(fh.fileno(), msvcrt.LK_NBLCK, 1)
PermissionError: [Errno 13] Permission denied

During handling of the above exception, another exception occurred:

Traceback (most recent call last):
  File "D:\UPBIT_ML\app.py", line 326, in worker
    module.main()
  File "D:\UPBIT_ML\f5_ml_pipeline\run_pipeline.py", line 99, in main
    lock = _acquire_lock()
  File "D:\UPBIT_ML\f5_ml_pipeline\run_pipeline.py", line 64, in _acquire_lock
    msvcrt.locking(fh.fileno(), msvcrt.LK_UNLCK, 1)
PermissionError: [Errno 13] Permission denied
2025-06-05 01:56:04,854 [WEB] ERROR pipeline error
Traceback (most recent call last):
  File "D:\UPBIT_ML\f5_ml_pipeline\run_pipeline.py", line 57, in _acquire_lock
    msvcrt.locking(fh.fileno(), msvcrt.LK_NBLCK, 1)
PermissionError: [Errno 13] Permission denied

During handling of the above exception, another exception occurred:

Traceback (most recent call last):
  File "D:\UPBIT_ML\app.py", line 326, in worker
    module.main()
  File "D:\UPBIT_ML\f5_ml_pipeline\run_pipeline.py", line 99, in main
    lock = _acquire_lock()
  File "D:\UPBIT_ML\f5_ml_pipeline\run_pipeline.py", line 64, in _acquire_lock
    msvcrt.locking(fh.fileno(), msvcrt.LK_UNLCK, 1)
PermissionError: [Errno 13] Permission denied
2025-06-05 02:04:06,538 [WEB] ERROR pipeline error
Traceback (most recent call last):
  File "D:\UPBIT_ML\f5_ml_pipeline\run_pipeline.py", line 57, in _acquire_lock
    msvcrt.locking(fh.fileno(), msvcrt.LK_NBLCK, 1)
PermissionError: [Errno 13] Permission denied

During handling of the above exception, another exception occurred:

Traceback (most recent call last):
  File "D:\UPBIT_ML\app.py", line 326, in worker
    module.main()
  File "D:\UPBIT_ML\f5_ml_pipeline\run_pipeline.py", line 99, in main
    lock = _acquire_lock()
  File "D:\UPBIT_ML\f5_ml_pipeline\run_pipeline.py", line 64, in _acquire_lock
    msvcrt.locking(fh.fileno(), msvcrt.LK_UNLCK, 1)
PermissionError: [Errno 13] Permission denied
2025-06-05 02:09:38,230 [WEB] ERROR pipeline error
Traceback (most recent call last):
  File "D:\UPBIT_ML\f5_ml_pipeline\run_pipeline.py", line 57, in _acquire_lock
    msvcrt.locking(fh.fileno(), msvcrt.LK_NBLCK, 1)
PermissionError: [Errno 13] Permission denied

During handling of the above exception, another exception occurred:

Traceback (most recent call last):
  File "D:\UPBIT_ML\app.py", line 326, in worker
    module.main()
  File "D:\UPBIT_ML\f5_ml_pipeline\run_pipeline.py", line 99, in main
    lock = _acquire_lock()
  File "D:\UPBIT_ML\f5_ml_pipeline\run_pipeline.py", line 64, in _acquire_lock
    msvcrt.locking(fh.fileno(), msvcrt.LK_UNLCK, 1)
PermissionError: [Errno 13] Permission denied
2025-06-05 02:17:43,082 [WEB] ERROR pipeline error
Traceback (most recent call last):
  File "D:\UPBIT_ML\f5_ml_pipeline\run_pipeline.py", line 57, in _acquire_lock
    msvcrt.locking(fh.fileno(), msvcrt.LK_NBLCK, 1)
PermissionError: [Errno 13] Permission denied

During handling of the above exception, another exception occurred:

Traceback (most recent call last):
  File "D:\UPBIT_ML\app.py", line 326, in worker
    module.main()
  File "D:\UPBIT_ML\f5_ml_pipeline\run_pipeline.py", line 99, in main
    lock = _acquire_lock()
  File "D:\UPBIT_ML\f5_ml_pipeline\run_pipeline.py", line 64, in _acquire_lock
    msvcrt.locking(fh.fileno(), msvcrt.LK_UNLCK, 1)
PermissionError: [Errno 13] Permission denied
2025-06-05 02:23:07,443 [WEB] ERROR pipeline error
Traceback (most recent call last):
  File "D:\UPBIT_ML\f5_ml_pipeline\run_pipeline.py", line 57, in _acquire_lock
    msvcrt.locking(fh.fileno(), msvcrt.LK_NBLCK, 1)
PermissionError: [Errno 13] Permission denied

During handling of the above exception, another exception occurred:

Traceback (most recent call last):
  File "D:\UPBIT_ML\app.py", line 326, in worker
    module.main()
  File "D:\UPBIT_ML\f5_ml_pipeline\run_pipeline.py", line 99, in main
    lock = _acquire_lock()
  File "D:\UPBIT_ML\f5_ml_pipeline\run_pipeline.py", line 64, in _acquire_lock
    msvcrt.locking(fh.fileno(), msvcrt.LK_UNLCK, 1)
PermissionError: [Errno 13] Permission denied
2025-06-05 02:31:21,916 [WEB] ERROR pipeline error
Traceback (most recent call last):
  File "D:\UPBIT_ML\f5_ml_pipeline\run_pipeline.py", line 57, in _acquire_lock
    msvcrt.locking(fh.fileno(), msvcrt.LK_NBLCK, 1)
PermissionError: [Errno 13] Permission denied

During handling of the above exception, another exception occurred:

Traceback (most recent call last):
  File "D:\UPBIT_ML\app.py", line 326, in worker
    module.main()
  File "D:\UPBIT_ML\f5_ml_pipeline\run_pipeline.py", line 99, in main
    lock = _acquire_lock()
  File "D:\UPBIT_ML\f5_ml_pipeline\run_pipeline.py", line 64, in _acquire_lock
    msvcrt.locking(fh.fileno(), msvcrt.LK_UNLCK, 1)
PermissionError: [Errno 13] Permission denied
2025-06-05 02:36:39,747 [WEB] ERROR pipeline error
Traceback (most recent call last):
  File "D:\UPBIT_ML\f5_ml_pipeline\run_pipeline.py", line 57, in _acquire_lock
    msvcrt.locking(fh.fileno(), msvcrt.LK_NBLCK, 1)
PermissionError: [Errno 13] Permission denied

During handling of the above exception, another exception occurred:

Traceback (most recent call last):
  File "D:\UPBIT_ML\app.py", line 326, in worker
    module.main()
  File "D:\UPBIT_ML\f5_ml_pipeline\run_pipeline.py", line 99, in main
    lock = _acquire_lock()
  File "D:\UPBIT_ML\f5_ml_pipeline\run_pipeline.py", line 64, in _acquire_lock
    msvcrt.locking(fh.fileno(), msvcrt.LK_UNLCK, 1)
PermissionError: [Errno 13] Permission denied
2025-06-05 02:44:30,166 [WEB] ERROR pipeline error
Traceback (most recent call last):
  File "D:\UPBIT_ML\f5_ml_pipeline\run_pipeline.py", line 57, in _acquire_lock
    msvcrt.locking(fh.fileno(), msvcrt.LK_NBLCK, 1)
PermissionError: [Errno 13] Permission denied

During handling of the above exception, another exception occurred:

Traceback (most recent call last):
  File "D:\UPBIT_ML\app.py", line 326, in worker
    module.main()
  File "D:\UPBIT_ML\f5_ml_pipeline\run_pipeline.py", line 99, in main
    lock = _acquire_lock()
  File "D:\UPBIT_ML\f5_ml_pipeline\run_pipeline.py", line 64, in _acquire_lock
    msvcrt.locking(fh.fileno(), msvcrt.LK_UNLCK, 1)
PermissionError: [Errno 13] Permission denied
2025-06-05 02:49:40,670 [WEB] ERROR pipeline error
Traceback (most recent call last):
  File "D:\UPBIT_ML\f5_ml_pipeline\run_pipeline.py", line 57, in _acquire_lock
    msvcrt.locking(fh.fileno(), msvcrt.LK_NBLCK, 1)
PermissionError: [Errno 13] Permission denied

During handling of the above exception, another exception occurred:

Traceback (most recent call last):
  File "D:\UPBIT_ML\app.py", line 326, in worker
    module.main()
  File "D:\UPBIT_ML\f5_ml_pipeline\run_pipeline.py", line 99, in main
    lock = _acquire_lock()
  File "D:\UPBIT_ML\f5_ml_pipeline\run_pipeline.py", line 64, in _acquire_lock
    msvcrt.locking(fh.fileno(), msvcrt.LK_UNLCK, 1)
PermissionError: [Errno 13] Permission denied
2025-06-05 03:06:10,430 [WEB] ERROR pipeline error
Traceback (most recent call last):
  File "D:\UPBIT_ML\f5_ml_pipeline\run_pipeline.py", line 57, in _acquire_lock
    msvcrt.locking(fh.fileno(), msvcrt.LK_NBLCK, 1)
PermissionError: [Errno 13] Permission denied

During handling of the above exception, another exception occurred:

Traceback (most recent call last):
  File "D:\UPBIT_ML\app.py", line 326, in worker
    module.main()
  File "D:\UPBIT_ML\f5_ml_pipeline\run_pipeline.py", line 99, in main
    lock = _acquire_lock()
  File "D:\UPBIT_ML\f5_ml_pipeline\run_pipeline.py", line 64, in _acquire_lock
    msvcrt.locking(fh.fileno(), msvcrt.LK_UNLCK, 1)
PermissionError: [Errno 13] Permission denied
2025-06-05 03:11:19,337 [WEB] ERROR pipeline error
Traceback (most recent call last):
  File "D:\UPBIT_ML\f5_ml_pipeline\run_pipeline.py", line 57, in _acquire_lock
    msvcrt.locking(fh.fileno(), msvcrt.LK_NBLCK, 1)
PermissionError: [Errno 13] Permission denied

During handling of the above exception, another exception occurred:

Traceback (most recent call last):
  File "D:\UPBIT_ML\app.py", line 326, in worker
    module.main()
  File "D:\UPBIT_ML\f5_ml_pipeline\run_pipeline.py", line 99, in main
    lock = _acquire_lock()
  File "D:\UPBIT_ML\f5_ml_pipeline\run_pipeline.py", line 64, in _acquire_lock
    msvcrt.locking(fh.fileno(), msvcrt.LK_UNLCK, 1)
PermissionError: [Errno 13] Permission denied
2025-06-05 03:19:44,906 [WEB] ERROR pipeline error
Traceback (most recent call last):
  File "D:\UPBIT_ML\f5_ml_pipeline\run_pipeline.py", line 57, in _acquire_lock
    msvcrt.locking(fh.fileno(), msvcrt.LK_NBLCK, 1)
PermissionError: [Errno 13] Permission denied

During handling of the above exception, another exception occurred:

Traceback (most recent call last):
  File "D:\UPBIT_ML\app.py", line 326, in worker
    module.main()
  File "D:\UPBIT_ML\f5_ml_pipeline\run_pipeline.py", line 99, in main
    lock = _acquire_lock()
  File "D:\UPBIT_ML\f5_ml_pipeline\run_pipeline.py", line 64, in _acquire_lock
    msvcrt.locking(fh.fileno(), msvcrt.LK_UNLCK, 1)
PermissionError: [Errno 13] Permission denied
2025-06-05 03:24:51,722 [WEB] ERROR pipeline error
Traceback (most recent call last):
  File "D:\UPBIT_ML\f5_ml_pipeline\run_pipeline.py", line 57, in _acquire_lock
    msvcrt.locking(fh.fileno(), msvcrt.LK_NBLCK, 1)
PermissionError: [Errno 13] Permission denied

During handling of the above exception, another exception occurred:

Traceback (most recent call last):
  File "D:\UPBIT_ML\app.py", line 326, in worker
    module.main()
  File "D:\UPBIT_ML\f5_ml_pipeline\run_pipeline.py", line 99, in main
    lock = _acquire_lock()
  File "D:\UPBIT_ML\f5_ml_pipeline\run_pipeline.py", line 64, in _acquire_lock
    msvcrt.locking(fh.fileno(), msvcrt.LK_UNLCK, 1)
PermissionError: [Errno 13] Permission denied
2025-06-05 03:32:59,191 [WEB] ERROR pipeline error
Traceback (most recent call last):
  File "D:\UPBIT_ML\f5_ml_pipeline\run_pipeline.py", line 57, in _acquire_lock
    msvcrt.locking(fh.fileno(), msvcrt.LK_NBLCK, 1)
PermissionError: [Errno 13] Permission denied

During handling of the above exception, another exception occurred:

Traceback (most recent call last):
  File "D:\UPBIT_ML\app.py", line 326, in worker
    module.main()
  File "D:\UPBIT_ML\f5_ml_pipeline\run_pipeline.py", line 99, in main
    lock = _acquire_lock()
  File "D:\UPBIT_ML\f5_ml_pipeline\run_pipeline.py", line 64, in _acquire_lock
    msvcrt.locking(fh.fileno(), msvcrt.LK_UNLCK, 1)
PermissionError: [Errno 13] Permission denied
2025-06-05 03:38:20,567 [WEB] ERROR pipeline error
Traceback (most recent call last):
  File "D:\UPBIT_ML\f5_ml_pipeline\run_pipeline.py", line 57, in _acquire_lock
    msvcrt.locking(fh.fileno(), msvcrt.LK_NBLCK, 1)
PermissionError: [Errno 13] Permission denied

During handling of the above exception, another exception occurred:

Traceback (most recent call last):
  File "D:\UPBIT_ML\app.py", line 326, in worker
    module.main()
  File "D:\UPBIT_ML\f5_ml_pipeline\run_pipeline.py", line 99, in main
    lock = _acquire_lock()
  File "D:\UPBIT_ML\f5_ml_pipeline\run_pipeline.py", line 64, in _acquire_lock
    msvcrt.locking(fh.fileno(), msvcrt.LK_UNLCK, 1)
PermissionError: [Errno 13] Permission denied
2025-06-05 03:46:31,786 [WEB] ERROR pipeline error
Traceback (most recent call last):
  File "D:\UPBIT_ML\f5_ml_pipeline\run_pipeline.py", line 57, in _acquire_lock
    msvcrt.locking(fh.fileno(), msvcrt.LK_NBLCK, 1)
PermissionError: [Errno 13] Permission denied

During handling of the above exception, another exception occurred:

Traceback (most recent call last):
  File "D:\UPBIT_ML\app.py", line 326, in worker
    module.main()
  File "D:\UPBIT_ML\f5_ml_pipeline\run_pipeline.py", line 99, in main
    lock = _acquire_lock()
  File "D:\UPBIT_ML\f5_ml_pipeline\run_pipeline.py", line 64, in _acquire_lock
    msvcrt.locking(fh.fileno(), msvcrt.LK_UNLCK, 1)
PermissionError: [Errno 13] Permission denied
2025-06-05 03:51:37,363 [WEB] ERROR pipeline error
Traceback (most recent call last):
  File "D:\UPBIT_ML\f5_ml_pipeline\run_pipeline.py", line 57, in _acquire_lock
    msvcrt.locking(fh.fileno(), msvcrt.LK_NBLCK, 1)
PermissionError: [Errno 13] Permission denied

During handling of the above exception, another exception occurred:

Traceback (most recent call last):
  File "D:\UPBIT_ML\app.py", line 326, in worker
    module.main()
  File "D:\UPBIT_ML\f5_ml_pipeline\run_pipeline.py", line 99, in main
    lock = _acquire_lock()
  File "D:\UPBIT_ML\f5_ml_pipeline\run_pipeline.py", line 64, in _acquire_lock
    msvcrt.locking(fh.fileno(), msvcrt.LK_UNLCK, 1)
PermissionError: [Errno 13] Permission denied
2025-06-05 03:59:57,825 [WEB] ERROR pipeline error
Traceback (most recent call last):
  File "D:\UPBIT_ML\f5_ml_pipeline\run_pipeline.py", line 57, in _acquire_lock
    msvcrt.locking(fh.fileno(), msvcrt.LK_NBLCK, 1)
PermissionError: [Errno 13] Permission denied

During handling of the above exception, another exception occurred:

Traceback (most recent call last):
  File "D:\UPBIT_ML\app.py", line 326, in worker
    module.main()
  File "D:\UPBIT_ML\f5_ml_pipeline\run_pipeline.py", line 99, in main
    lock = _acquire_lock()
  File "D:\UPBIT_ML\f5_ml_pipeline\run_pipeline.py", line 64, in _acquire_lock
    msvcrt.locking(fh.fileno(), msvcrt.LK_UNLCK, 1)
PermissionError: [Errno 13] Permission denied
2025-06-05 04:05:00,880 [WEB] ERROR pipeline error
Traceback (most recent call last):
  File "D:\UPBIT_ML\f5_ml_pipeline\run_pipeline.py", line 57, in _acquire_lock
    msvcrt.locking(fh.fileno(), msvcrt.LK_NBLCK, 1)
PermissionError: [Errno 13] Permission denied

During handling of the above exception, another exception occurred:

Traceback (most recent call last):
  File "D:\UPBIT_ML\app.py", line 326, in worker
    module.main()
  File "D:\UPBIT_ML\f5_ml_pipeline\run_pipeline.py", line 99, in main
    lock = _acquire_lock()
  File "D:\UPBIT_ML\f5_ml_pipeline\run_pipeline.py", line 64, in _acquire_lock
    msvcrt.locking(fh.fileno(), msvcrt.LK_UNLCK, 1)
PermissionError: [Errno 13] Permission denied
2025-06-05 04:13:04,711 [WEB] ERROR pipeline error
Traceback (most recent call last):
  File "D:\UPBIT_ML\f5_ml_pipeline\run_pipeline.py", line 57, in _acquire_lock
    msvcrt.locking(fh.fileno(), msvcrt.LK_NBLCK, 1)
PermissionError: [Errno 13] Permission denied

During handling of the above exception, another exception occurred:

Traceback (most recent call last):
  File "D:\UPBIT_ML\app.py", line 326, in worker
    module.main()
  File "D:\UPBIT_ML\f5_ml_pipeline\run_pipeline.py", line 99, in main
    lock = _acquire_lock()
  File "D:\UPBIT_ML\f5_ml_pipeline\run_pipeline.py", line 64, in _acquire_lock
    msvcrt.locking(fh.fileno(), msvcrt.LK_UNLCK, 1)
PermissionError: [Errno 13] Permission denied
2025-06-05 04:18:25,045 [WEB] ERROR pipeline error
Traceback (most recent call last):
  File "D:\UPBIT_ML\f5_ml_pipeline\run_pipeline.py", line 57, in _acquire_lock
    msvcrt.locking(fh.fileno(), msvcrt.LK_NBLCK, 1)
PermissionError: [Errno 13] Permission denied

During handling of the above exception, another exception occurred:

Traceback (most recent call last):
  File "D:\UPBIT_ML\app.py", line 326, in worker
    module.main()
  File "D:\UPBIT_ML\f5_ml_pipeline\run_pipeline.py", line 99, in main
    lock = _acquire_lock()
  File "D:\UPBIT_ML\f5_ml_pipeline\run_pipeline.py", line 64, in _acquire_lock
    msvcrt.locking(fh.fileno(), msvcrt.LK_UNLCK, 1)
PermissionError: [Errno 13] Permission denied
2025-06-05 04:34:44,814 [WEB] ERROR pipeline error
Traceback (most recent call last):
  File "D:\UPBIT_ML\f5_ml_pipeline\run_pipeline.py", line 57, in _acquire_lock
    msvcrt.locking(fh.fileno(), msvcrt.LK_NBLCK, 1)
PermissionError: [Errno 13] Permission denied

During handling of the above exception, another exception occurred:

Traceback (most recent call last):
  File "D:\UPBIT_ML\app.py", line 326, in worker
    module.main()
  File "D:\UPBIT_ML\f5_ml_pipeline\run_pipeline.py", line 99, in main
    lock = _acquire_lock()
  File "D:\UPBIT_ML\f5_ml_pipeline\run_pipeline.py", line 64, in _acquire_lock
    msvcrt.locking(fh.fileno(), msvcrt.LK_UNLCK, 1)
PermissionError: [Errno 13] Permission denied
2025-06-05 04:39:50,271 [WEB] ERROR pipeline error
Traceback (most recent call last):
  File "D:\UPBIT_ML\f5_ml_pipeline\run_pipeline.py", line 57, in _acquire_lock
    msvcrt.locking(fh.fileno(), msvcrt.LK_NBLCK, 1)
PermissionError: [Errno 13] Permission denied

During handling of the above exception, another exception occurred:

Traceback (most recent call last):
  File "D:\UPBIT_ML\app.py", line 326, in worker
    module.main()
  File "D:\UPBIT_ML\f5_ml_pipeline\run_pipeline.py", line 99, in main
    lock = _acquire_lock()
  File "D:\UPBIT_ML\f5_ml_pipeline\run_pipeline.py", line 64, in _acquire_lock
    msvcrt.locking(fh.fileno(), msvcrt.LK_UNLCK, 1)
PermissionError: [Errno 13] Permission denied
2025-06-05 04:48:00,277 [WEB] ERROR pipeline error
Traceback (most recent call last):
  File "D:\UPBIT_ML\f5_ml_pipeline\run_pipeline.py", line 57, in _acquire_lock
    msvcrt.locking(fh.fileno(), msvcrt.LK_NBLCK, 1)
PermissionError: [Errno 13] Permission denied

During handling of the above exception, another exception occurred:

Traceback (most recent call last):
  File "D:\UPBIT_ML\app.py", line 326, in worker
    module.main()
  File "D:\UPBIT_ML\f5_ml_pipeline\run_pipeline.py", line 99, in main
    lock = _acquire_lock()
  File "D:\UPBIT_ML\f5_ml_pipeline\run_pipeline.py", line 64, in _acquire_lock
    msvcrt.locking(fh.fileno(), msvcrt.LK_UNLCK, 1)
PermissionError: [Errno 13] Permission denied
2025-06-05 04:53:13,731 [WEB] ERROR pipeline error
Traceback (most recent call last):
  File "D:\UPBIT_ML\f5_ml_pipeline\run_pipeline.py", line 57, in _acquire_lock
    msvcrt.locking(fh.fileno(), msvcrt.LK_NBLCK, 1)
PermissionError: [Errno 13] Permission denied

During handling of the above exception, another exception occurred:

Traceback (most recent call last):
  File "D:\UPBIT_ML\app.py", line 326, in worker
    module.main()
  File "D:\UPBIT_ML\f5_ml_pipeline\run_pipeline.py", line 99, in main
    lock = _acquire_lock()
  File "D:\UPBIT_ML\f5_ml_pipeline\run_pipeline.py", line 64, in _acquire_lock
    msvcrt.locking(fh.fileno(), msvcrt.LK_UNLCK, 1)
PermissionError: [Errno 13] Permission denied
2025-06-05 05:01:25,049 [WEB] ERROR pipeline error
Traceback (most recent call last):
  File "D:\UPBIT_ML\f5_ml_pipeline\run_pipeline.py", line 57, in _acquire_lock
    msvcrt.locking(fh.fileno(), msvcrt.LK_NBLCK, 1)
PermissionError: [Errno 13] Permission denied

During handling of the above exception, another exception occurred:

Traceback (most recent call last):
  File "D:\UPBIT_ML\app.py", line 326, in worker
    module.main()
  File "D:\UPBIT_ML\f5_ml_pipeline\run_pipeline.py", line 99, in main
    lock = _acquire_lock()
  File "D:\UPBIT_ML\f5_ml_pipeline\run_pipeline.py", line 64, in _acquire_lock
    msvcrt.locking(fh.fileno(), msvcrt.LK_UNLCK, 1)
PermissionError: [Errno 13] Permission denied
2025-06-05 05:06:39,603 [WEB] ERROR pipeline error
Traceback (most recent call last):
  File "D:\UPBIT_ML\f5_ml_pipeline\run_pipeline.py", line 57, in _acquire_lock
    msvcrt.locking(fh.fileno(), msvcrt.LK_NBLCK, 1)
PermissionError: [Errno 13] Permission denied

During handling of the above exception, another exception occurred:

Traceback (most recent call last):
  File "D:\UPBIT_ML\app.py", line 326, in worker
    module.main()
  File "D:\UPBIT_ML\f5_ml_pipeline\run_pipeline.py", line 99, in main
    lock = _acquire_lock()
  File "D:\UPBIT_ML\f5_ml_pipeline\run_pipeline.py", line 64, in _acquire_lock
    msvcrt.locking(fh.fileno(), msvcrt.LK_UNLCK, 1)
PermissionError: [Errno 13] Permission denied
2025-06-05 05:14:38,490 [WEB] ERROR pipeline error
Traceback (most recent call last):
  File "D:\UPBIT_ML\f5_ml_pipeline\run_pipeline.py", line 57, in _acquire_lock
    msvcrt.locking(fh.fileno(), msvcrt.LK_NBLCK, 1)
PermissionError: [Errno 13] Permission denied

During handling of the above exception, another exception occurred:

Traceback (most recent call last):
  File "D:\UPBIT_ML\app.py", line 326, in worker
    module.main()
  File "D:\UPBIT_ML\f5_ml_pipeline\run_pipeline.py", line 99, in main
    lock = _acquire_lock()
  File "D:\UPBIT_ML\f5_ml_pipeline\run_pipeline.py", line 64, in _acquire_lock
    msvcrt.locking(fh.fileno(), msvcrt.LK_UNLCK, 1)
PermissionError: [Errno 13] Permission denied
2025-06-05 05:19:46,955 [WEB] ERROR pipeline error
Traceback (most recent call last):
  File "D:\UPBIT_ML\f5_ml_pipeline\run_pipeline.py", line 57, in _acquire_lock
    msvcrt.locking(fh.fileno(), msvcrt.LK_NBLCK, 1)
PermissionError: [Errno 13] Permission denied

During handling of the above exception, another exception occurred:

Traceback (most recent call last):
  File "D:\UPBIT_ML\app.py", line 326, in worker
    module.main()
  File "D:\UPBIT_ML\f5_ml_pipeline\run_pipeline.py", line 99, in main
    lock = _acquire_lock()
  File "D:\UPBIT_ML\f5_ml_pipeline\run_pipeline.py", line 64, in _acquire_lock
    msvcrt.locking(fh.fileno(), msvcrt.LK_UNLCK, 1)
PermissionError: [Errno 13] Permission denied
2025-06-05 05:27:48,233 [WEB] ERROR pipeline error
Traceback (most recent call last):
  File "D:\UPBIT_ML\f5_ml_pipeline\run_pipeline.py", line 57, in _acquire_lock
    msvcrt.locking(fh.fileno(), msvcrt.LK_NBLCK, 1)
PermissionError: [Errno 13] Permission denied

During handling of the above exception, another exception occurred:

Traceback (most recent call last):
  File "D:\UPBIT_ML\app.py", line 326, in worker
    module.main()
  File "D:\UPBIT_ML\f5_ml_pipeline\run_pipeline.py", line 99, in main
    lock = _acquire_lock()
  File "D:\UPBIT_ML\f5_ml_pipeline\run_pipeline.py", line 64, in _acquire_lock
    msvcrt.locking(fh.fileno(), msvcrt.LK_UNLCK, 1)
PermissionError: [Errno 13] Permission denied
2025-06-05 05:33:14,258 [WEB] ERROR pipeline error
Traceback (most recent call last):
  File "D:\UPBIT_ML\f5_ml_pipeline\run_pipeline.py", line 57, in _acquire_lock
    msvcrt.locking(fh.fileno(), msvcrt.LK_NBLCK, 1)
PermissionError: [Errno 13] Permission denied

During handling of the above exception, another exception occurred:

Traceback (most recent call last):
  File "D:\UPBIT_ML\app.py", line 326, in worker
    module.main()
  File "D:\UPBIT_ML\f5_ml_pipeline\run_pipeline.py", line 99, in main
    lock = _acquire_lock()
  File "D:\UPBIT_ML\f5_ml_pipeline\run_pipeline.py", line 64, in _acquire_lock
    msvcrt.locking(fh.fileno(), msvcrt.LK_UNLCK, 1)
PermissionError: [Errno 13] Permission denied
2025-06-05 05:41:17,344 [WEB] ERROR pipeline error
Traceback (most recent call last):
  File "D:\UPBIT_ML\f5_ml_pipeline\run_pipeline.py", line 57, in _acquire_lock
    msvcrt.locking(fh.fileno(), msvcrt.LK_NBLCK, 1)
PermissionError: [Errno 13] Permission denied

During handling of the above exception, another exception occurred:

Traceback (most recent call last):
  File "D:\UPBIT_ML\app.py", line 326, in worker
    module.main()
  File "D:\UPBIT_ML\f5_ml_pipeline\run_pipeline.py", line 99, in main
    lock = _acquire_lock()
  File "D:\UPBIT_ML\f5_ml_pipeline\run_pipeline.py", line 64, in _acquire_lock
    msvcrt.locking(fh.fileno(), msvcrt.LK_UNLCK, 1)
PermissionError: [Errno 13] Permission denied
2025-06-05 05:46:32,856 [WEB] ERROR pipeline error
Traceback (most recent call last):
  File "D:\UPBIT_ML\f5_ml_pipeline\run_pipeline.py", line 57, in _acquire_lock
    msvcrt.locking(fh.fileno(), msvcrt.LK_NBLCK, 1)
PermissionError: [Errno 13] Permission denied

During handling of the above exception, another exception occurred:

Traceback (most recent call last):
  File "D:\UPBIT_ML\app.py", line 326, in worker
    module.main()
  File "D:\UPBIT_ML\f5_ml_pipeline\run_pipeline.py", line 99, in main
    lock = _acquire_lock()
  File "D:\UPBIT_ML\f5_ml_pipeline\run_pipeline.py", line 64, in _acquire_lock
    msvcrt.locking(fh.fileno(), msvcrt.LK_UNLCK, 1)
PermissionError: [Errno 13] Permission denied
2025-06-05 05:54:46,402 [WEB] ERROR pipeline error
Traceback (most recent call last):
  File "D:\UPBIT_ML\f5_ml_pipeline\run_pipeline.py", line 57, in _acquire_lock
    msvcrt.locking(fh.fileno(), msvcrt.LK_NBLCK, 1)
PermissionError: [Errno 13] Permission denied

During handling of the above exception, another exception occurred:

Traceback (most recent call last):
  File "D:\UPBIT_ML\app.py", line 326, in worker
    module.main()
  File "D:\UPBIT_ML\f5_ml_pipeline\run_pipeline.py", line 99, in main
    lock = _acquire_lock()
  File "D:\UPBIT_ML\f5_ml_pipeline\run_pipeline.py", line 64, in _acquire_lock
    msvcrt.locking(fh.fileno(), msvcrt.LK_UNLCK, 1)
PermissionError: [Errno 13] Permission denied
2025-06-05 06:00:02,866 [WEB] ERROR pipeline error
Traceback (most recent call last):
  File "D:\UPBIT_ML\f5_ml_pipeline\run_pipeline.py", line 57, in _acquire_lock
    msvcrt.locking(fh.fileno(), msvcrt.LK_NBLCK, 1)
PermissionError: [Errno 13] Permission denied

During handling of the above exception, another exception occurred:

Traceback (most recent call last):
  File "D:\UPBIT_ML\app.py", line 326, in worker
    module.main()
  File "D:\UPBIT_ML\f5_ml_pipeline\run_pipeline.py", line 99, in main
    lock = _acquire_lock()
  File "D:\UPBIT_ML\f5_ml_pipeline\run_pipeline.py", line 64, in _acquire_lock
    msvcrt.locking(fh.fileno(), msvcrt.LK_UNLCK, 1)
PermissionError: [Errno 13] Permission denied
2025-06-05 06:07:58,044 [WEB] ERROR pipeline error
Traceback (most recent call last):
  File "D:\UPBIT_ML\f5_ml_pipeline\run_pipeline.py", line 57, in _acquire_lock
    msvcrt.locking(fh.fileno(), msvcrt.LK_NBLCK, 1)
PermissionError: [Errno 13] Permission denied

During handling of the above exception, another exception occurred:

Traceback (most recent call last):
  File "D:\UPBIT_ML\app.py", line 326, in worker
    module.main()
  File "D:\UPBIT_ML\f5_ml_pipeline\run_pipeline.py", line 99, in main
    lock = _acquire_lock()
  File "D:\UPBIT_ML\f5_ml_pipeline\run_pipeline.py", line 64, in _acquire_lock
    msvcrt.locking(fh.fileno(), msvcrt.LK_UNLCK, 1)
PermissionError: [Errno 13] Permission denied
2025-06-05 06:13:22,242 [WEB] ERROR pipeline error
Traceback (most recent call last):
  File "D:\UPBIT_ML\f5_ml_pipeline\run_pipeline.py", line 57, in _acquire_lock
    msvcrt.locking(fh.fileno(), msvcrt.LK_NBLCK, 1)
PermissionError: [Errno 13] Permission denied

During handling of the above exception, another exception occurred:

Traceback (most recent call last):
  File "D:\UPBIT_ML\app.py", line 326, in worker
    module.main()
  File "D:\UPBIT_ML\f5_ml_pipeline\run_pipeline.py", line 99, in main
    lock = _acquire_lock()
  File "D:\UPBIT_ML\f5_ml_pipeline\run_pipeline.py", line 64, in _acquire_lock
    msvcrt.locking(fh.fileno(), msvcrt.LK_UNLCK, 1)
PermissionError: [Errno 13] Permission denied
2025-06-05 06:21:36,419 [WEB] ERROR pipeline error
Traceback (most recent call last):
  File "D:\UPBIT_ML\f5_ml_pipeline\run_pipeline.py", line 57, in _acquire_lock
    msvcrt.locking(fh.fileno(), msvcrt.LK_NBLCK, 1)
PermissionError: [Errno 13] Permission denied

During handling of the above exception, another exception occurred:

Traceback (most recent call last):
  File "D:\UPBIT_ML\app.py", line 326, in worker
    module.main()
  File "D:\UPBIT_ML\f5_ml_pipeline\run_pipeline.py", line 99, in main
    lock = _acquire_lock()
  File "D:\UPBIT_ML\f5_ml_pipeline\run_pipeline.py", line 64, in _acquire_lock
    msvcrt.locking(fh.fileno(), msvcrt.LK_UNLCK, 1)
PermissionError: [Errno 13] Permission denied
2025-06-05 06:27:02,031 [WEB] ERROR pipeline error
Traceback (most recent call last):
  File "D:\UPBIT_ML\f5_ml_pipeline\run_pipeline.py", line 57, in _acquire_lock
    msvcrt.locking(fh.fileno(), msvcrt.LK_NBLCK, 1)
PermissionError: [Errno 13] Permission denied

During handling of the above exception, another exception occurred:

Traceback (most recent call last):
  File "D:\UPBIT_ML\app.py", line 326, in worker
    module.main()
  File "D:\UPBIT_ML\f5_ml_pipeline\run_pipeline.py", line 99, in main
    lock = _acquire_lock()
  File "D:\UPBIT_ML\f5_ml_pipeline\run_pipeline.py", line 64, in _acquire_lock
    msvcrt.locking(fh.fileno(), msvcrt.LK_UNLCK, 1)
PermissionError: [Errno 13] Permission denied
2025-06-05 06:35:02,029 [WEB] ERROR pipeline error
Traceback (most recent call last):
  File "D:\UPBIT_ML\f5_ml_pipeline\run_pipeline.py", line 57, in _acquire_lock
    msvcrt.locking(fh.fileno(), msvcrt.LK_NBLCK, 1)
PermissionError: [Errno 13] Permission denied

During handling of the above exception, another exception occurred:

Traceback (most recent call last):
  File "D:\UPBIT_ML\app.py", line 326, in worker
    module.main()
  File "D:\UPBIT_ML\f5_ml_pipeline\run_pipeline.py", line 99, in main
    lock = _acquire_lock()
  File "D:\UPBIT_ML\f5_ml_pipeline\run_pipeline.py", line 64, in _acquire_lock
    msvcrt.locking(fh.fileno(), msvcrt.LK_UNLCK, 1)
PermissionError: [Errno 13] Permission denied
2025-06-05 06:40:37,979 [WEB] ERROR pipeline error
Traceback (most recent call last):
  File "D:\UPBIT_ML\f5_ml_pipeline\run_pipeline.py", line 57, in _acquire_lock
    msvcrt.locking(fh.fileno(), msvcrt.LK_NBLCK, 1)
PermissionError: [Errno 13] Permission denied

During handling of the above exception, another exception occurred:

Traceback (most recent call last):
  File "D:\UPBIT_ML\app.py", line 326, in worker
    module.main()
  File "D:\UPBIT_ML\f5_ml_pipeline\run_pipeline.py", line 99, in main
    lock = _acquire_lock()
  File "D:\UPBIT_ML\f5_ml_pipeline\run_pipeline.py", line 64, in _acquire_lock
    msvcrt.locking(fh.fileno(), msvcrt.LK_UNLCK, 1)
PermissionError: [Errno 13] Permission denied
2025-06-05 06:48:27,097 [WEB] ERROR pipeline error
Traceback (most recent call last):
  File "D:\UPBIT_ML\f5_ml_pipeline\run_pipeline.py", line 57, in _acquire_lock
    msvcrt.locking(fh.fileno(), msvcrt.LK_NBLCK, 1)
PermissionError: [Errno 13] Permission denied

During handling of the above exception, another exception occurred:

Traceback (most recent call last):
  File "D:\UPBIT_ML\app.py", line 326, in worker
    module.main()
  File "D:\UPBIT_ML\f5_ml_pipeline\run_pipeline.py", line 99, in main
    lock = _acquire_lock()
  File "D:\UPBIT_ML\f5_ml_pipeline\run_pipeline.py", line 64, in _acquire_lock
    msvcrt.locking(fh.fileno(), msvcrt.LK_UNLCK, 1)
PermissionError: [Errno 13] Permission denied
2025-06-05 06:53:36,789 [WEB] ERROR pipeline error
Traceback (most recent call last):
  File "D:\UPBIT_ML\f5_ml_pipeline\run_pipeline.py", line 57, in _acquire_lock
    msvcrt.locking(fh.fileno(), msvcrt.LK_NBLCK, 1)
PermissionError: [Errno 13] Permission denied

During handling of the above exception, another exception occurred:

Traceback (most recent call last):
  File "D:\UPBIT_ML\app.py", line 326, in worker
    module.main()
  File "D:\UPBIT_ML\f5_ml_pipeline\run_pipeline.py", line 99, in main
    lock = _acquire_lock()
  File "D:\UPBIT_ML\f5_ml_pipeline\run_pipeline.py", line 64, in _acquire_lock
    msvcrt.locking(fh.fileno(), msvcrt.LK_UNLCK, 1)
PermissionError: [Errno 13] Permission denied
