2025-06-04 19:43:25,776 [WEB] ERROR pipeline error
Traceback (most recent call last):
  File "D:\UPBIT_ML\f5_ml_pipeline\run_pipeline.py", line 57, in _acquire_lock
    msvcrt.locking(fh.fileno(), msvcrt.LK_NBLCK, 1)
PermissionError: [Errno 13] Permission denied

During handling of the above exception, another exception occurred:

Traceback (most recent call last):
  File "D:\UPBIT_ML\app.py", line 326, in worker
    module.main()
  File "D:\UPBIT_ML\f5_ml_pipeline\run_pipeline.py", line 99, in main
    lock = _acquire_lock()
  File "D:\UPBIT_ML\f5_ml_pipeline\run_pipeline.py", line 64, in _acquire_lock
    msvcrt.locking(fh.fileno(), msvcrt.LK_UNLCK, 1)
PermissionError: [Errno 13] Permission denied
2025-06-04 19:50:15,860 [WEB] ERROR pipeline error
Traceback (most recent call last):
  File "D:\UPBIT_ML\f5_ml_pipeline\run_pipeline.py", line 57, in _acquire_lock
    msvcrt.locking(fh.fileno(), msvcrt.LK_NBLCK, 1)
PermissionError: [Errno 13] Permission denied

During handling of the above exception, another exception occurred:

Traceback (most recent call last):
  File "D:\UPBIT_ML\app.py", line 326, in worker
    module.main()
  File "D:\UPBIT_ML\f5_ml_pipeline\run_pipeline.py", line 99, in main
    lock = _acquire_lock()
  File "D:\UPBIT_ML\f5_ml_pipeline\run_pipeline.py", line 64, in _acquire_lock
    msvcrt.locking(fh.fileno(), msvcrt.LK_UNLCK, 1)
PermissionError: [Errno 13] Permission denied
2025-06-04 19:55:27,250 [WEB] ERROR pipeline error
Traceback (most recent call last):
  File "D:\UPBIT_ML\f5_ml_pipeline\run_pipeline.py", line 57, in _acquire_lock
    msvcrt.locking(fh.fileno(), msvcrt.LK_NBLCK, 1)
PermissionError: [Errno 13] Permission denied

During handling of the above exception, another exception occurred:

Traceback (most recent call last):
  File "D:\UPBIT_ML\app.py", line 326, in worker
    module.main()
  File "D:\UPBIT_ML\f5_ml_pipeline\run_pipeline.py", line 99, in main
    lock = _acquire_lock()
  File "D:\UPBIT_ML\f5_ml_pipeline\run_pipeline.py", line 64, in _acquire_lock
    msvcrt.locking(fh.fileno(), msvcrt.LK_UNLCK, 1)
PermissionError: [Errno 13] Permission denied
2025-06-04 20:02:15,247 [WEB] ERROR pipeline error
Traceback (most recent call last):
  File "D:\UPBIT_ML\f5_ml_pipeline\run_pipeline.py", line 57, in _acquire_lock
    msvcrt.locking(fh.fileno(), msvcrt.LK_NBLCK, 1)
PermissionError: [Errno 13] Permission denied

During handling of the above exception, another exception occurred:

Traceback (most recent call last):
  File "D:\UPBIT_ML\app.py", line 326, in worker
    module.main()
  File "D:\UPBIT_ML\f5_ml_pipeline\run_pipeline.py", line 99, in main
    lock = _acquire_lock()
  File "D:\UPBIT_ML\f5_ml_pipeline\run_pipeline.py", line 64, in _acquire_lock
    msvcrt.locking(fh.fileno(), msvcrt.LK_UNLCK, 1)
PermissionError: [Errno 13] Permission denied
2025-06-04 20:07:31,632 [WEB] ERROR pipeline error
Traceback (most recent call last):
  File "D:\UPBIT_ML\f5_ml_pipeline\run_pipeline.py", line 57, in _acquire_lock
    msvcrt.locking(fh.fileno(), msvcrt.LK_NBLCK, 1)
PermissionError: [Errno 13] Permission denied

During handling of the above exception, another exception occurred:

Traceback (most recent call last):
  File "D:\UPBIT_ML\app.py", line 326, in worker
    module.main()
  File "D:\UPBIT_ML\f5_ml_pipeline\run_pipeline.py", line 99, in main
    lock = _acquire_lock()
  File "D:\UPBIT_ML\f5_ml_pipeline\run_pipeline.py", line 64, in _acquire_lock
    msvcrt.locking(fh.fileno(), msvcrt.LK_UNLCK, 1)
PermissionError: [Errno 13] Permission denied
2025-06-04 20:14:26,511 [WEB] ERROR pipeline error
Traceback (most recent call last):
  File "D:\UPBIT_ML\f5_ml_pipeline\run_pipeline.py", line 57, in _acquire_lock
    msvcrt.locking(fh.fileno(), msvcrt.LK_NBLCK, 1)
PermissionError: [Errno 13] Permission denied

During handling of the above exception, another exception occurred:

Traceback (most recent call last):
  File "D:\UPBIT_ML\app.py", line 326, in worker
    module.main()
  File "D:\UPBIT_ML\f5_ml_pipeline\run_pipeline.py", line 99, in main
    lock = _acquire_lock()
  File "D:\UPBIT_ML\f5_ml_pipeline\run_pipeline.py", line 64, in _acquire_lock
    msvcrt.locking(fh.fileno(), msvcrt.LK_UNLCK, 1)
PermissionError: [Errno 13] Permission denied
2025-06-04 20:19:52,566 [WEB] ERROR pipeline error
Traceback (most recent call last):
  File "D:\UPBIT_ML\f5_ml_pipeline\run_pipeline.py", line 57, in _acquire_lock
    msvcrt.locking(fh.fileno(), msvcrt.LK_NBLCK, 1)
PermissionError: [Errno 13] Permission denied

During handling of the above exception, another exception occurred:

Traceback (most recent call last):
  File "D:\UPBIT_ML\app.py", line 326, in worker
    module.main()
  File "D:\UPBIT_ML\f5_ml_pipeline\run_pipeline.py", line 99, in main
    lock = _acquire_lock()
  File "D:\UPBIT_ML\f5_ml_pipeline\run_pipeline.py", line 64, in _acquire_lock
    msvcrt.locking(fh.fileno(), msvcrt.LK_UNLCK, 1)
PermissionError: [Errno 13] Permission denied
2025-06-04 20:27:06,739 [WEB] ERROR pipeline error
Traceback (most recent call last):
  File "D:\UPBIT_ML\f5_ml_pipeline\run_pipeline.py", line 57, in _acquire_lock
    msvcrt.locking(fh.fileno(), msvcrt.LK_NBLCK, 1)
PermissionError: [Errno 13] Permission denied

During handling of the above exception, another exception occurred:

Traceback (most recent call last):
  File "D:\UPBIT_ML\app.py", line 326, in worker
    module.main()
  File "D:\UPBIT_ML\f5_ml_pipeline\run_pipeline.py", line 99, in main
    lock = _acquire_lock()
  File "D:\UPBIT_ML\f5_ml_pipeline\run_pipeline.py", line 64, in _acquire_lock
    msvcrt.locking(fh.fileno(), msvcrt.LK_UNLCK, 1)
PermissionError: [Errno 13] Permission denied
